Workbook

Sheet _Inicio
B1: Registro de visitantes, cantón Patate
B2: Cada establecimiento anota aquí sus visitantes por mes. El tablero se actualiza solo, cada pocos minutos.
B4: Cómo agregar un establecimiento
B5: 1. Duplique la pestaña Plantilla | C5: Clic derecho sobre la pestaña Plantilla y elija Duplicar.
B6: 2. Renombre la copia | C6: Use el nombre del local. Ese nombre es el que aparece en el tablero.
B7: 3. Llene una fila por mes, origen y motivo | C7: Escriba el año, el mes, el país, la ciudad (solo si es Ecuador) y el motivo. Luego escriba cuántas mujeres y cuántos hombres hubo en cada rango de edad.
B8: 4. Espere unos minutos | C8: El establecimiento aparece solo en el tablero.
B10: Qué escribe usted y qué calcula la hoja
B11: Año, Mes, País, Ciudad, Motivo | C11: Con la lista desplegable. Para extranjeros deje la ciudad vacía.
B12: Mujeres y Hombres por rango de edad | C12: Ocho números enteros: 0-30, 31-45, 46-60 y 61 o más años. Si no hubo, déjelo vacío o escriba 0.
B13: Personas con discapacidad | C13: Cuántas de esas personas tenían alguna discapacidad. No puede superar el total de visitantes de la fila.
B14: Columnas grises | C14: Provincia, Total mujeres, Total hombres, Total visitantes, Nacionales, Extranjeros y Estado las calcula la hoja: no se escriben.
B15: Estado | C15: Dice OK cuando la fila está bien. Si no, la fila se pinta de rojo y explica qué corregir. Una fila en rojo no se publica en el tablero.
B17: Qué es cada pestaña
B18: Pestaña | C18: Para qué sirve | D18: ¿Se edita?
B19: _Inicio | C19: Esta guía. El tablero no la lee. | D19: No
B20: _Catalogos | C20: Las opciones de los desplegables, en cuatro bloques: Listas, Países, Ciudades y Provincias. Agregue al final de cada bloque. Para ordenar, seleccione el bloque completo (Datos > Ordenar rango). | D20: Solo al final de cada lista
B21: Plantilla | C21: Modelo vacío con los desplegables y las fórmulas. Se duplica, no se llena. | D21: No
B22: Las demás | C22: Un establecimiento cada una. | D22: Sí, cada local la suya
B24: Reglas
B25: • No cambie ni mueva los encabezados de las columnas.
B26: • Use siempre los desplegables. Extranjeros: deje vacía la ciudad.
B27: • No escriba datos personales: ni nombres, ni cédulas, ni teléfonos. La discapacidad se publica solo como cifra agregada.
B28: • Para que nadie escriba sobre las columnas grises, protéjalas en Google Sheets: Datos > Proteger hojas y rangos.
B29: • Las pestañas que todavía usan el formato anterior (Cantidad, Edad y Género) siguen funcionando. No mezcle los dos formatos en una misma pestaña.

Sheet _Catalogos
A1: Año | B1: Mes | C1: Motivo | D1: Género | F1: País | G1: Pais_Lat | H1: Pais_Lon | J1: Ciudad | K1: Ciudad_Provincia | L1: Ciudad_Lat | M1: Ciudad_Lon | O1: Provincia | P1: Provincia_Lat | Q1: Provincia_Lon
A2: 2025 | B2: Enero | C2: Turismo | D2: Masculino | F2: Afganistán | G2: 33 | H2: 65 | J2: 24 de Mayo | K2: Manabí | L2: -1.3829 | M2: -80.3748 | O2: Azuay | P2: -3.02 | Q2: -79.15
A3: 2026 | B3: Febrero | C3: Gastronomía | D3: Femenino | F3: Albania | G3: 41 | H3: 20 | J3: Aguarico | K3: Orellana | L3: -0.9497 | M3: -75.8822 | O3: Bolívar | P3: -1.59 | Q3: -79.11
A4: 2027 | B4: Marzo | C4: Descanso | D4: Otro | F4: Alemania | G4: 51.1657 | H4: 10.4515 | J4: Alausí | K4: Chimborazo | L4: -2.2 | M4: -78.85 | O4: Cañar | P4: -2.54 | Q4: -79.02
B5: Abril | C5: Visita familiar | F5: Andorra | G5: 42.5 | H5: 1.5 | J5: Alfredo Baquerizo Moreno | K5: Guayas | L5: -1.9469 | M5: -79.5474 | O5: Carchi | P5: 0.77 | Q5: -78.08
B6: Mayo | C6: Evento | F6: Angola | G6: -12.5 | H6: 18.5 | J6: Ambato | K6: Tungurahua | L6: -1.2491 | M6: -78.6168 | O6: Chimborazo | P6: -1.97 | Q6: -78.72
B7: Junio | C7: Negocios | F7: Antigua y Barbuda | G7: 17.05 | H7: -61.8 | J7: Arajuno | K7: Pastaza | L7: -1.3189 | M7: -76.73 | O7: Cotopaxi | P7: -0.86 | Q7: -78.86
B8: Julio | C8: Ocio | F8: Arabia Saudí | G8: 25 | H8: 45 | J8: Archidona | K8: Napo | L8: -0.91 | M8: -77.81 | O8: El Oro | P8: -3.51 | Q8: -79.83
B9: Agosto | F9: Argelia | G9: 28 | H9: 3 | J9: Arenillas | K9: El Oro | L9: -3.55 | M9: -80.06 | O9: Esmeraldas | P9: 0.72 | Q9: -79.22
B10: Septiembre | F10: Argentina | G10: -38.4161 | H10: -63.6167 | J10: Atacames | K10: Esmeraldas | L10: 0.87 | M10: -79.84 | O10: Galápagos | P10: -0.56 | Q10: -90.91
B11: Octubre | F11: Armenia | G11: 40 | H11: 45 | J11: Atahualpa | K11: El Oro | L11: -3.5531 | M11: -79.717 | O11: Guayas | P11: -2.11 | Q11: -79.88
B12: Noviembre | F12: Australia | G12: -35.28 | H12: 149.13 | J12: Atuntaqui | K12: Imbabura | L12: 0.33 | M12: -78.22 | O12: Imbabura | P12: 0.41 | Q12: -78.37
B13: Diciembre | F13: Austria | G13: 48.21 | H13: 16.37 | J13: Ayampe | K13: Manabí | L13: -1.68 | M13: -80.8 | O13: Loja | P13: -4.09 | Q13: -79.65
F14: Azerbaiyán | G14: 40.5 | H14: 47.5 | J14: Azogues | K14: Cañar | L14: -2.7397 | M14: -78.8486 | O14: Los Ríos | P14: -1.35 | Q14: -79.49
F15: Bahamas | G15: 24.25 | H15: -76 | J15: Baba | K15: Los Ríos | L15: -1.681 | M15: -79.6611 | O15: Manabí | P15: -0.76 | Q15: -80.14
F16: Bahrein | G16: 26 | H16: 50.55 | J16: Babahoyo | K16: Los Ríos | L16: -1.8022 | M16: -79.5344 | O16: Morona Santiago | P16: -2.56 | Q16: -78.01
F17: Bangladesh | G17: 24 | H17: 90 | J17: Baeza | K17: Napo | L17: -0.46 | M17: -77.89 | O17: Napo | P17: -0.65 | Q17: -77.82
F18: Barbados | G18: 13.166667 | H18: -59.533333 | J18: Bahía de Caráquez | K18: Manabí | L18: -0.6 | M18: -80.42 | O18: Orellana | P18: -0.78 | Q18: -76.36
F19: Bélgica | G19: 50.85 | H19: 4.35 | J19: Balao | K19: Guayas | L19: -2.8926 | M19: -79.7341 | O19: Pastaza | P19: -1.71 | Q19: -76.87
F20: Belice | G20: 17.25 | H20: -88.77 | J20: Balsas | K20: El Oro | L20: -3.7688 | M20: -79.8377 | O20: Pichincha | P20: -0.11 | Q20: -78.6
F21: Benín | G21: 9.5 | H21: 2.25 | J21: Balzar | K21: Guayas | L21: -1.36 | M21: -79.9 | O21: Santa Elena | P21: -2.14 | Q21: -80.58
F22: Bielorrusia | G22: 53 | H22: 28 | J22: Baños | K22: Tungurahua | L22: -1.3964 | M22: -78.4247 | O22: Santo Domingo de los Tsáchilas | P22: -0.26 | Q22: -79.22
F23: Bolivia | G23: -16.49 | H23: -68.15 | J23: Baños de Agua Santa | K23: Tungurahua | L23: -1.3366 | M23: -78.2734 | O23: Sucumbíos | P23: -0.01 | Q23: -76.57
F24: Bosnia y Herzegovina | G24: 44 | H24: 18 | J24: Biblián | K24: Cañar | L24: -2.72 | M24: -78.89 | O24: Tungurahua | P24: -1.29 | Q24: -78.51
F25: Botswana | G25: -22 | H25: 24 | J25: Bolívar (Carchi) | K25: Carchi | L25: 0.4756 | M25: -77.9228 | O25: Zamora Chinchipe | P25: -4.17 | Q25: -78.91
F26: Brasil | G26: -15.79 | H26: -47.88 | J26: Bolívar (Manabí) | K26: Manabí | L26: -0.9095 | M26: -80.0339
F27: Brunei | G27: 4.5 | H27: 114.66667 | J27: Buena Fe | K27: Los Ríos | L27: -0.89 | M27: -79.49
F28: Bulgaria | G28: 43 | H28: 25 | J28: Caluma | K28: Bolívar | L28: -1.63 | M28: -79.25
F29: Burkina Faso | G29: 13 | H29: -2 | J29: Camilo Ponce Enríquez | K29: Azuay | L29: -2.9778 | M29: -79.5986
F30: Burundi | G30: -3.5 | H30: 30 | J30: Canoa | K30: Manabí | L30: -0.46 | M30: -80.46
F31: Bután | G31: 27.5 | H31: 90.5 | J31: Cañar | K31: Cañar | L31: -2.56 | M31: -78.94
F32: Cabo Verde | G32: 16 | H32: -24 | J32: Cariamanga | K32: Loja | L32: -4.33 | M32: -79.55
F33: Camboya | G33: 13 | H33: 105 | J33: Carlos Julio Arosemena Tola | K33: Napo | L33: -1.1641 | M33: -77.94
F34: Camerún | G34: 6 | H34: 12 | J34: Cascales | K34: Sucumbíos | L34: 0.1458 | M34: -77.2329
F35: Canadá | G35: 56.1304 | H35: -106.3468 | J35: Catamayo | K35: Loja | L35: -3.99 | M35: -79.36
F36: Catar | G36: 25.5 | H36: 51.25 | J36: Cayambe | K36: Pichincha | L36: 0.04 | M36: -78.15
F37: Chad | G37: 15 | H37: 19 | J37: Celica | K37: Loja | L37: -4.1677 | M37: -80.0296
... F196: Zimbabue | G196: -20 | H196: 30 | J196: San Vicente | K196: Manabí | L196: -0.4775 | M196: -80.3592
J197: Sangolquí | K197: Pichincha | L197: -0.31 | M197: -78.45
J198: Santa Ana | K198: Manabí | L198: -1.1961 | M198: -80.2124
...

Sheet Plantilla
A1: Año | B1: Mes | C1: País | D1: Provincia | E1: Ciudad | F1: Motivo de visita | G1: Mujeres 0-30 | H1: Mujeres 31-45 | I1: Mujeres 46-60 | J1: Mujeres 61+ | K1: Hombres 0-30 | L1: Hombres 31-45 | M1: Hombres 46-60 | N1: Hombres 61+ | O1: Personas con discapacidad | P1: Total mujeres | Q1: Total hombres | R1: Total visitantes | S1: Nacionales | T1: Extranjeros | U1: Estado
D2: =IF(E2="","",IFERROR(VLOOKUP(E2,'_Catalogos'!$J$2:$K$1000,2,FALSE),"")) | P2: =IF(COUNT(G2:O2)=0,"",SUM(G2:J2)) | Q2: =IF(COUNT(G2:O2)=0,"",SUM(K2:N2)) | R2: =IF(P2="","",P2+Q2) | S2: =IF(R2="","",IF(C2="Ecuador",R2,0)) | T2: =IF(R2="","",R2-S2) | U2: =IF(R2="","",IF(O2>R2,"Revisar: discapacidad "&O2&" mayor que el total "&R2,IF(OR(A2="",B2="",C2="",F2=""),"Falta año, mes, país o motivo",IF(AND(C2="Ecuador",E2=""),"Falta la ciudad","OK"))))
D3: =IF(E3="","",IFERROR(VLOOKUP(E3,'_Catalogos'!$J$2:$K$1000,2,FALSE),"")) | P3: =IF(COUNT(G3:O3)=0,"",SUM(G3:J3)) | Q3: =IF(COUNT(G3:O3)=0,"",SUM(K3:N3)) | R3: =IF(P3="","",P3+Q3) | S3: =IF(R3="","",IF(C3="Ecuador",R3,0)) | T3: =IF(R3="","",R3-S3) | U3: =IF(R3="","",IF(O3>R3,"Revisar: discapacidad "&O3&" mayor que el total "&R3,IF(OR(A3="",B3="",C3="",F3=""),"Falta año, mes, país o motivo",IF(AND(C3="Ecuador",E3=""),"Falta la ciudad","OK"))))
D4: =IF(E4="","",IFERROR(VLOOKUP(E4,'_Catalogos'!$J$2:$K$1000,2,FALSE),"")) | P4: =IF(COUNT(G4:O4)=0,"",SUM(G4:J4)) | Q4: =IF(COUNT(G4:O4)=0,"",SUM(K4:N4)) | R4: =IF(P4="","",P4+Q4) | S4: =IF(R4="","",IF(C4="Ecuador",R4,0)) | T4: =IF(R4="","",R4-S4) | U4: =IF(R4="","",IF(O4>R4,"Revisar: discapacidad "&O4&" mayor que el total "&R4,IF(OR(A4="",B4="",C4="",F4=""),"Falta año, mes, país o motivo",IF(AND(C4="Ecuador",E4=""),"Falta la ciudad","OK"))))
D5: =IF(E5="","",IFERROR(VLOOKUP(E5,'_Catalogos'!$J$2:$K$1000,2,FALSE),"")) | P5: =IF(COUNT(G5:O5)=0,"",SUM(G5:J5)) | Q5: =IF(COUNT(G5:O5)=0,"",SUM(K5:N5)) | R5: =IF(P5="","",P5+Q5) | S5: =IF(R5="","",IF(C5="Ecuador",R5,0)) | T5: =IF(R5="","",R5-S5) | U5: =IF(R5="","",IF(O5>R5,"Revisar: discapacidad "&O5&" mayor que el total "&R5,IF(OR(A5="",B5="",C5="",F5=""),"Falta año, mes, país o motivo",IF(AND(C5="Ecuador",E5=""),"Falta la ciudad","OK"))))
D6: =IF(E6="","",IFERROR(VLOOKUP(E6,'_Catalogos'!$J$2:$K$1000,2,FALSE),"")) | P6: =IF(COUNT(G6:O6)=0,"",SUM(G6:J6)) | Q6: =IF(COUNT(G6:O6)=0,"",SUM(K6:N6)) | R6: =IF(P6="","",P6+Q6) | S6: =IF(R6="","",IF(C6="Ecuador",R6,0)) | T6: =IF(R6="","",R6-S6) | U6: =IF(R6="","",IF(O6>R6,"Revisar: discapacidad "&O6&" mayor que el total "&R6,IF(OR(A6="",B6="",C6="",F6=""),"Falta año, mes, país o motivo",IF(AND(C6="Ecuador",E6=""),"Falta la ciudad","OK"))))
D7: =IF(E7="","",IFERROR(VLOOKUP(E7,'_Catalogos'!$J$2:$K$1000,2,FALSE),"")) | P7: =IF(COUNT(G7:O7)=0,"",SUM(G7:J7)) | Q7: =IF(COUNT(G7:O7)=0,"",SUM(K7:N7)) | R7: =IF(P7="","",P7+Q7) | S7: =IF(R7="","",IF(C7="Ecuador",R7,0)) | T7: =IF(R7="","",R7-S7) | U7: =IF(R7="","",IF(O7>R7,"Revisar: discapacidad "&O7&" mayor que el total "&R7,IF(OR(A7="",B7="",C7="",F7=""),"Falta año, mes, país o motivo",IF(AND(C7="Ecuador",E7=""),"Falta la ciudad","OK"))))
D8: =IF(E8="","",IFERROR(VLOOKUP(E8,'_Catalogos'!$J$2:$K$1000,2,FALSE),"")) | P8: =IF(COUNT(G8:O8)=0,"",SUM(G8:J8)) | Q8: =IF(COUNT(G8:O8)=0,"",SUM(K8:N8)) | R8: =IF(P8="","",P8+Q8) | S8: =IF(R8="","",IF(C8="Ecuador",R8,0)) | T8: =IF(R8="","",R8-S8) | U8: =IF(R8="","",IF(O8>R8,"Revisar: discapacidad "&O8&" mayor que el total "&R8,IF(OR(A8="",B8="",C8="",F8=""),"Falta año, mes, país o motivo",IF(AND(C8="Ecuador",E8=""),"Falta la ciudad","OK"))))
D9: =IF(E9="","",IFERROR(VLOOKUP(E9,'_Catalogos'!$J$2:$K$1000,2,FALSE),"")) | P9: =IF(COUNT(G9:O9)=0,"",SUM(G9:J9)) | Q9: =IF(COUNT(G9:O9)=0,"",SUM(K9:N9)) | R9: =IF(P9="","",P9+Q9) | S9: =IF(R9="","",IF(C9="Ecuador",R9,0)) | T9: =IF(R9="","",R9-S9) | U9: =IF(R9="","",IF(O9>R9,"Revisar: discapacidad "&O9&" mayor que el total "&R9,IF(OR(A9="",B9="",C9="",F9=""),"Falta año, mes, país o motivo",IF(AND(C9="Ecuador",E9=""),"Falta la ciudad","OK"))))
D10: =IF(E10="","",IFERROR(VLOOKUP(E10,'_Catalogos'!$J$2:$K$1000,2,FALSE),"")) | P10: =IF(COUNT(G10:O10)=0,"",SUM(G10:J10)) | Q10: =IF(COUNT(G10:O10)=0,"",SUM(K10:N10)) | R10: =IF(P10="","",P10+Q10) | S10: =IF(R10="","",IF(C10="Ecuador",R10,0)) | T10: =IF(R10="","",R10-S10) | U10: =IF(R10="","",IF(O10>R10,"Revisar: discapacidad "&O10&" mayor que el total "&R10,IF(OR(A10="",B10="",C10="",F10=""),"Falta año, mes, país o motivo",IF(AND(C10="Ecuador",E10=""),"Falta la ciudad","OK"))))
D11: =IF(E11="","",IFERROR(VLOOKUP(E11,'_Catalogos'!$J$2:$K$1000,2,FALSE),"")) | P11: =IF(COUNT(G11:O11)=0,"",SUM(G11:J11)) | Q11: =IF(COUNT(G11:O11)=0,"",SUM(K11:N11)) | R11: =IF(P11="","",P11+Q11) | S11: =IF(R11="","",IF(C11="Ecuador",R11,0)) | T11: =IF(R11="","",R11-S11) | U11: =IF(R11="","",IF(O11>R11,"Revisar: discapacidad "&O11&" mayor que el total "&R11,IF(OR(A11="",B11="",C11="",F11=""),"Falta año, mes, país o motivo",IF(AND(C11="Ecuador",E11=""),"Falta la ciudad","OK"))))
D12: =IF(E12="","",IFERROR(VLOOKUP(E12,'_Catalogos'!$J$2:$K$1000,2,FALSE),"")) | P12: =IF(COUNT(G12:O12)=0,"",SUM(G12:J12)) | Q12: =IF(COUNT(G12:O12)=0,"",SUM(K12:N12)) | R12: =IF(P12="","",P12+Q12) | S12: =IF(R12="","",IF(C12="Ecuador",R12,0)) | T12: =IF(R12="","",R12-S12) | U12: =IF(R12="","",IF(O12>R12,"Revisar: discapacidad "&O12&" mayor que el total "&R12,IF(OR(A12="",B12="",C12="",F12=""),"Falta año, mes, país o motivo",IF(AND(C12="Ecuador",E12=""),"Falta la ciudad","OK"))))
D13: =IF(E13="","",IFERROR(VLOOKUP(E13,'_Catalogos'!$J$2:$K$1000,2,FALSE),"")) | P13: =IF(COUNT(G13:O13)=0,"",SUM(G13:J13)) | Q13: =IF(COUNT(G13:O13)=0,"",SUM(K13:N13)) | R13: =IF(P13="","",P13+Q13) | S13: =IF(R13="","",IF(C13="Ecuador",R13,0)) | T13: =IF(R13="","",R13-S13) | U13: =IF(R13="","",IF(O13>R13,"Revisar: discapacidad "&O13&" mayor que el total "&R13,IF(OR(A13="",B13="",C13="",F13=""),"Falta año, mes, país o motivo",IF(AND(C13="Ecuador",E13=""),"Falta la ciudad","OK"))))
... D600: =IF(E600="","",IFERROR(VLOOKUP(E600,'_Catalogos'!$J$2:$K$1000,2,FALSE),"")) | P600: =IF(COUNT(G600:O600)=0,"",SUM(G600:J600)) | Q600: =IF(COUNT(G600:O600)=0,"",SUM(K600:N600)) | R600: =IF(P600="","",P600+Q600) | S600: =IF(R600="","",IF(C600="Ecuador",R600,0)) | T600: =IF(R600="","",R600-S600) | U600: =IF(R600="","",IF(O600>R600,"Revisar: discapacidad "&O600&" mayor que el total "&R600,IF(OR(A600="",B600="",C600="",F600=""),"Falta año, mes, país o motivo",IF(AND(C600="Ecuador",E600=""),"Falta la ciudad","OK"))))

Sheet Heladería Las Orquídeas
A1: Año | B1: Mes | C1: País | D1: Provincia | E1: Ciudad | F1: Motivo de visita | G1: Mujeres 0-30 | H1: Mujeres 31-45 | I1: Mujeres 46-60 | J1: Mujeres 61+ | K1: Hombres 0-30 | L1: Hombres 31-45 | M1: Hombres 46-60 | N1: Hombres 61+ | O1: Personas con discapacidad | P1: Total mujeres | Q1: Total hombres | R1: Total visitantes | S1: Nacionales | T1: Extranjeros | U1: Estado
A2: 2025 | B2: Enero | C2: Ecuador | D2: =IF(E2="","",IFERROR(VLOOKUP(E2,'_Catalogos'!$J$2:$K$1000,2,FALSE),"")) -> Tungurahua | E2: Baños | F2: Visita familiar | G2: 4 | H2: 1 | I2: 2 | K2: 2 | M2: 1 | P2: =IF(COUNT(G2:O2)=0,"",SUM(G2:J2)) -> 7 | Q2: =IF(COUNT(G2:O2)=0,"",SUM(K2:N2)) -> 3 | R2: =IF(P2="","",P2+Q2) -> 10 | S2: =IF(R2="","",IF(C2="Ecuador",R2,0)) -> 10 | T2: =IF(R2="","",R2-S2) -> 0 | U2: =IF(R2="","",IF(O2>R2,"Revisar: discapacidad "&O2&" mayor que el total "&R2,IF(OR(A2="",B2="",C2="",F2=""),"Falta año, mes, país o motivo",IF(AND(C2="Ecuador",E2=""),"Falta la ciudad","OK")))) -> OK
A3: 2025 | B3: Enero | C3: España | D3: =IF(E3="","",IFERROR(VLOOKUP(E3,'_Catalogos'!$J$2:$K$1000,2,FALSE),"")) | F3: Descanso | H3: 1 | I3: 2 | L3: 2 | P3: =IF(COUNT(G3:O3)=0,"",SUM(G3:J3)) -> 3 | Q3: =IF(COUNT(G3:O3)=0,"",SUM(K3:N3)) -> 2 | R3: =IF(P3="","",P3+Q3) -> 5 | S3: =IF(R3="","",IF(C3="Ecuador",R3,0)) -> 0 | T3: =IF(R3="","",R3-S3) -> 5 | U3: =IF(R3="","",IF(O3>R3,"Revisar: discapacidad "&O3&" mayor que el total "&R3,IF(OR(A3="",B3="",C3="",F3=""),"Falta año, mes, país o motivo",IF(AND(C3="Ecuador",E3=""),"Falta la ciudad","OK")))) -> OK
A4: 2025 | B4: Enero | C4: Ecuador | D4: =IF(E4="","",IFERROR(VLOOKUP(E4,'_Catalogos'!$J$2:$K$1000,2,FALSE),"")) -> Imbabura | E4: Ibarra | F4: Gastronomía | G4: 2 | I4: 1 | J4: 2 | K4: 1 | M4: 1 | P4: =IF(COUNT(G4:O4)=0,"",SUM(G4:J4)) -> 5 | Q4: =IF(COUNT(G4:O4)=0,"",SUM(K4:N4)) -> 2 | R4: =IF(P4="","",P4+Q4) -> 7 | S4: =IF(R4="","",IF(C4="Ecuador",R4,0)) -> 7 | T4: =IF(R4="","",R4-S4) -> 0 | U4: =IF(R4="","",IF(O4>R4,"Revisar: discapacidad "&O4&" mayor que el total "&R4,IF(OR(A4="",B4="",C4="",F4=""),"Falta año, mes, país o motivo",IF(AND(C4="Ecuador",E4=""),"Falta la ciudad","OK")))) -> OK
A5: 2025 | B5: Febrero | C5: Ecuador | D5: =IF(E5="","",IFERROR(VLOOKUP(E5,'_Catalogos'!$J$2:$K$1000,2,FALSE),"")) -> Azuay | E5: Cuenca | F5: Turismo | G5: 3 | H5: 1 | I5: 1 | K5: 2 | M5: 2 | P5: =IF(COUNT(G5:O5)=0,"",SUM(G5:J5)) -> 5 | Q5: =IF(COUNT(G5:O5)=0,"",SUM(K5:N5)) -> 4 | R5: =IF(P5="","",P5+Q5) -> 9 | S5: =IF(R5="","",IF(C5="Ecuador",R5,0)) -> 9 | T5: =IF(R5="","",R5-S5) -> 0 | U5: =IF(R5="","",IF(O5>R5,"Revisar: discapacidad "&O5&" mayor que el total "&R5,IF(OR(A5="",B5="",C5="",F5=""),"Falta año, mes, país o motivo",IF(AND(C5="Ecuador",E5=""),"Falta la ciudad","OK")))) -> OK
A6: 2025 | B6: Febrero | C6: Ecuador | D6: =IF(E6="","",IFERROR(VLOOKUP(E6,'_Catalogos'!$J$2:$K$1000,2,FALSE),"")) -> Cotopaxi | E6: Salcedo | F6: Turismo | G6: 1 | H6: 2 | I6: 2 | K6: 1 | L6: 1 | M6: 1 | N6: 2 | P6: =IF(COUNT(G6:O6)=0,"",SUM(G6:J6)) -> 5 | Q6: =IF(COUNT(G6:O6)=0,"",SUM(K6:N6)) -> 5 | R6: =IF(P6="","",P6+Q6) -> 10 | S6: =IF(R6="","",IF(C6="Ecuador",R6,0)) -> 10 | T6: =IF(R6="","",R6-S6) -> 0 | U6: =IF(R6="","",IF(O6>R6,"Revisar: discapacidad "&O6&" mayor que el total "&R6,IF(OR(A6="",B6="",C6="",F6=""),"Falta año, mes, país o motivo",IF(AND(C6="Ecuador",E6=""),"Falta la ciudad","OK")))) -> OK
A7: 2025 | B7: Marzo | C7: Colombia | D7: =IF(E7="","",IFERROR(VLOOKUP(E7,'_Catalogos'!$J$2:$K$1000,2,FALSE),"")) | F7: Gastronomía | H7: 3 | I7: 1 | K7: 1 | M7: 2 | P7: =IF(COUNT(G7:O7)=0,"",SUM(G7:J7)) -> 4 | Q7: =IF(COUNT(G7:O7)=0,"",SUM(K7:N7)) -> 3 | R7: =IF(P7="","",P7+Q7) -> 7 | S7: =IF(R7="","",IF(C7="Ecuador",R7,0)) -> 0 | T7: =IF(R7="","",R7-S7) -> 7 | U7: =IF(R7="","",IF(O7>R7,"Revisar: discapacidad "&O7&" mayor que el total "&R7,IF(OR(A7="",B7="",C7="",F7=""),"Falta año, mes, país o motivo",IF(AND(C7="Ecuador",E7=""),"Falta la ciudad","OK")))) -> OK
A8: 2025 | B8: Marzo | C8: Ecuador | D8: =IF(E8="","",IFERROR(VLOOKUP(E8,'_Catalogos'!$J$2:$K$1000,2,FALSE),"")) -> Guayas | E8: Guayaquil | F8: Turismo | H8: 1 | K8: 1 | L8: 2 | M8: 1 | P8: =IF(COUNT(G8:O8)=0,"",SUM(G8:J8)) -> 1 | Q8: =IF(COUNT(G8:O8)=0,"",SUM(K8:N8)) -> 4 | R8: =IF(P8="","",P8+Q8) -> 5 | S8: =IF(R8="","",IF(C8="Ecuador",R8,0)) -> 5 | T8: =IF(R8="","",R8-S8) -> 0 | U8: =IF(R8="","",IF(O8>R8,"Revisar: discapacidad "&O8&" mayor que el total "&R8,IF(OR(A8="",B8="",C8="",F8=""),"Falta año, mes, país o motivo",IF(AND(C8="Ecuador",E8=""),"Falta la ciudad","OK")))) -> OK
A9: 2025 | B9: Marzo | C9: Ecuador | D9: =IF(E9="","",IFERROR(VLOOKUP(E9,'_Catalogos'!$J$2:$K$1000,2,FALSE),"")) -> Pichincha | E9: Quito | F9: Turismo | G9: 1 | H9: 1 | I9: 2 | L9: 1 | M9: 1 | P9: =IF(COUNT(G9:O9)=0,"",SUM(G9:J9)) -> 4 | Q9: =IF(COUNT(G9:O9)=0,"",SUM(K9:N9)) -> 2 | R9: =IF(P9="","",P9+Q9) -> 6 | S9: =IF(R9="","",IF(C9="Ecuador",R9,0)) -> 6 | T9: =IF(R9="","",R9-S9) -> 0 | U9: =IF(R9="","",IF(O9>R9,"Revisar: discapacidad "&O9&" mayor que el total "&R9,IF(OR(A9="",B9="",C9="",F9=""),"Falta año, mes, país o motivo",IF(AND(C9="Ecuador",E9=""),"Falta la ciudad","OK")))) -> OK
A10: 2025 | B10: Marzo | C10: Chile | D10: =IF(E10="","",IFERROR(VLOOKUP(E10,'_Catalogos'!$J$2:$K$1000,2,FALSE),"")) | F10: Turismo | I10: 1 | K10: 1 | O10: 2 | P10: =IF(COUNT(G10:O10)=0,"",SUM(G10:J10)) -> 1 | Q10: =IF(COUNT(G10:O10)=0,"",SUM(K10:N10)) -> 1 | R10: =IF(P10="","",P10+Q10) -> 2 | S10: =IF(R10="","",IF(C10="Ecuador",R10,0)) -> 0 | T10: =IF(R10="","",R10-S10) -> 2 | U10: =IF(R10="","",IF(O10>R10,"Revisar: discapacidad "&O10&" mayor que el total "&R10,IF(OR(A10="",B10="",C10="",F10=""),"Falta año, mes, país o motivo",IF(AND(C10="Ecuador",E10=""),"Falta la ciudad","OK")))) -> OK
A11: 2025 | B11: Abril | C11: Ecuador | D11: =IF(E11="","",IFERROR(VLOOKUP(E11,'_Catalogos'!$J$2:$K$1000,2,FALSE),"")) -> Tungurahua | E11: Ambato | F11: Gastronomía | H11: 2 | J11: 1 | K11: 1 | L11: 3 | M11: 2 | N11: 1 | P11: =IF(COUNT(G11:O11)=0,"",SUM(G11:J11)) -> 3 | Q11: =IF(COUNT(G11:O11)=0,"",SUM(K11:N11)) -> 7 | R11: =IF(P11="","",P11+Q11) -> 10 | S11: =IF(R11="","",IF(C11="Ecuador",R11,0)) -> 10 | T11: =IF(R11="","",R11-S11) -> 0 | U11: =IF(R11="","",IF(O11>R11,"Revisar: discapacidad "&O11&" mayor que el total "&R11,IF(OR(A11="",B11="",C11="",F11=""),"Falta año, mes, país o motivo",IF(AND(C11="Ecuador",E11=""),"Falta la ciudad","OK")))) -> OK
A12: 2025 | B12: Abril | C12: Ecuador | D12: =IF(E12="","",IFERROR(VLOOKUP(E12,'_Catalogos'!$J$2:$K$1000,2,FALSE),"")) -> Pichincha | E12: Quito | F12: Turismo | H12: 1 | I12: 1 | M12: 1 | P12: =IF(COUNT(G12:O12)=0,"",SUM(G12:J12)) -> 2 | Q12: =IF(COUNT(G12:O12)=0,"",SUM(K12:N12)) -> 1 | R12: =IF(P12="","",P12+Q12) -> 3 | S12: =IF(R12="","",IF(C12="Ecuador",R12,0)) -> 3 | T12: =IF(R12="","",R12-S12) -> 0 | U12: =IF(R12="","",IF(O12>R12,"Revisar: discapacidad "&O12&" mayor que el total "&R12,IF(OR(A12="",B12="",C12="",F12=""),"Falta año, mes, país o motivo",IF(AND(C12="Ecuador",E12=""),"Falta la ciudad","OK")))) -> OK
A13: 2025 | B13: Abril | C13: Ecuador | D13: =IF(E13="","",IFERROR(VLOOKUP(E13,'_Catalogos'!$J$2:$K$1000,2,FALSE),"")) -> Tungurahua | E13: Pelileo | F13: Turismo | G13: 1 | H13: 2 | K13: 1 | L13: 1 | N13: 1 | P13: =IF(COUNT(G13:O13)=0,"",SUM(G13:J13)) -> 3 | Q13: =IF(COUNT(G13:O13)=0,"",SUM(K13:N13)) -> 3 | R13: =IF(P13="","",P13+Q13) -> 6 | S13: =IF(R13="","",IF(C13="Ecuador",R13,0)) -> 6 | T13: =IF(R13="","",R13-S13) -> 0 | U13: =IF(R13="","",IF(O13>R13,"Revisar: discapacidad "&O13&" mayor que el total "&R13,IF(OR(A13="",B13="",C13="",F13=""),"Falta año, mes, país o motivo",IF(AND(C13="Ecuador",E13=""),"Falta la ciudad","OK")))) -> OK
A14: 2025 | B14: Abril | C14: Ecuador | D14: =IF(E14="","",IFERROR(VLOOKUP(E14,'_Catalogos'!$J$2:$K$1000,2,FALSE),"")) -> Loja | E14: Loja | F14: Descanso | G14: 1 | I14: 1 | M14: 1 | N14: 1 | P14: =IF(COUNT(G14:O14)=0,"",SUM(G14:J14)) -> 2 | Q14: =IF(COUNT(G14:O14)=0,"",SUM(K14:N14)) -> 2 | R14: =IF(P14="","",P14+Q14) -> 4 | S14: =IF(R14="","",IF(C14="Ecuador",R14,0)) -> 4 | T14: =IF(R14="","",R14-S14) -> 0 | U14: =IF(R14="","",IF(O14>R14,"Revisar: discapacidad "&O14&" mayor que el total "&R14,IF(OR(A14="",B14="",C14="",F14=""),"Falta año, mes, país o motivo",IF(AND(C14="Ecuador",E14=""),"Falta la ciudad","OK")))) -> OK
A15: 2025 | B15: Mayo | C15: Ecuador | D15: =IF(E15="","",IFERROR(VLOOKUP(E15,'_Catalogos'!$J$2:$K$1000,2,FALSE),"")) -> Tungurahua | E15: Ambato | F15: Gastronomía | G15: 1 | J15: 1 | L15: 3 | O15: 5 | P15: =IF(COUNT(G15:O15)=0,"",SUM(G15:J15)) -> 2 | Q15: =IF(COUNT(G15:O15)=0,"",SUM(K15:N15)) -> 3 | R15: =IF(P15="","",P15+Q15) -> 5 | S15: =IF(R15="","",IF(C15="Ecuador",R15,0)) -> 5 | T15: =IF(R15="","",R15-S15) -> 0 | U15: =IF(R15="","",IF(O15>R15,"Revisar: discapacidad "&O15&" mayor que el total "&R15,IF(OR(A15="",B15="",C15="",F15=""),"Falta año, mes, país o motivo",IF(AND(C15="Ecuador",E15=""),"Falta la ciudad","OK")))) -> OK
A16: 2025 | B16: Mayo | C16: Ecuador | D16: =IF(E16="","",IFERROR(VLOOKUP(E16,'_Catalogos'!$J$2:$K$1000,2,FALSE),"")) -> Chimborazo | E16: Riobamba | F16: Gastronomía | I16: 1 | M16: 1 | P16: =IF(COUNT(G16:O16)=0,"",SUM(G16:J16)) -> 1 | Q16: =IF(COUNT(G16:O16)=0,"",SUM(K16:N16)) -> 1 | R16: =IF(P16="","",P16+Q16) -> 2 | S16: =IF(R16="","",IF(C16="Ecuador",R16,0)) -> 2 | T16: =IF(R16="","",R16-S16) -> 0 | U16: =IF(R16="","",IF(O16>R16,"Revisar: discapacidad "&O16&" mayor que el total "&R16,IF(OR(A16="",B16="",C16="",F16=""),"Falta año, mes, país o motivo",IF(AND(C16="Ecuador",E16=""),"Falta la ciudad","OK")))) -> OK
A17: 2025 | B17: Junio | C17: Ecuador | D17: =IF(E17="","",IFERROR(VLOOKUP(E17,'_Catalogos'!$J$2:$K$1000,2,FALSE),"")) -> Pichincha | E17: Quito | F17: Evento | G17: 1 | H17: 1 | I17: 2 | J17: 1 | N17: 1 | P17: =IF(COUNT(G17:O17)=0,"",SUM(G17:J17)) -> 5 | Q17: =IF(COUNT(G17:O17)=0,"",SUM(K17:N17)) -> 1 | R17: =IF(P17="","",P17+Q17) -> 6 | S17: =IF(R17="","",IF(C17="Ecuador",R17,0)) -> 6 | T17: =IF(R17="","",R17-S17) -> 0 | U17: =IF(R17="","",IF(O17>R17,"Revisar: discapacidad "&O17&" mayor que el total "&R17,IF(OR(A17="",B17="",C17="",F17=""),"Falta año, mes, país o motivo",IF(AND(C17="Ecuador",E17=""),"Falta la ciudad","OK")))) -> OK
A18: 2025 | B18: Junio | C18: Ecuador | D18: =IF(E18="","",IFERROR(VLOOKUP(E18,'_Catalogos'!$J$2:$K$1000,2,FALSE),"")) -> Pastaza | E18: Puyo | F18: Turismo | G18: 1 | I18: 1 | K18: 1 | L18: 1 | P18: =IF(COUNT(G18:O18)=0,"",SUM(G18:J18)) -> 2 | Q18: =IF(COUNT(G18:O18)=0,"",SUM(K18:N18)) -> 2 | R18: =IF(P18="","",P18+Q18) -> 4 | S18: =IF(R18="","",IF(C18="Ecuador",R18,0)) -> 4 | T18: =IF(R18="","",R18-S18) -> 0 | U18: =IF(R18="","",IF(O18>R18,"Revisar: discapacidad "&O18&" mayor que el total "&R18,IF(OR(A18="",B18="",C18="",F18=""),"Falta año, mes, país o motivo",IF(AND(C18="Ecuador",E18=""),"Falta la ciudad","OK")))) -> OK
A19: 2025 | B19: Junio | C19: Ecuador | D19: =IF(E19="","",IFERROR(VLOOKUP(E19,'_Catalogos'!$J$2:$K$1000,2,FALSE),"")) -> Carchi | E19: Huaca | F19: Descanso | H19: 3 | I19: 1 | K19: 2 | N19: 1 | P19: =IF(COUNT(G19:O19)=0,"",SUM(G19:J19)) -> 4 | Q19: =IF(COUNT(G19:O19)=0,"",SUM(K19:N19)) -> 3 | R19: =IF(P19="","",P19+Q19) -> 7 | S19: =IF(R19="","",IF(C19="Ecuador",R19,0)) -> 7 | T19: =IF(R19="","",R19-S19) -> 0 | U19: =IF(R19="","",IF(O19>R19,"Revisar: discapacidad "&O19&" mayor que el total "&R19,IF(OR(A19="",B19="",C19="",F19=""),"Falta año, mes, país o motivo",IF(AND(C19="Ecuador",E19=""),"Falta la ciudad","OK")))) -> OK
A20: 2025 | B20: Junio | C20: España | D20: =IF(E20="","",IFERROR(VLOOKUP(E20,'_Catalogos'!$J$2:$K$1000,2,FALSE),"")) | F20: Visita familiar | G20: 1 | H20: 1 | M20: 1 | P20: =IF(COUNT(G20:O20)=0,"",SUM(G20:J20)) -> 2 | Q20: =IF(COUNT(G20:O20)=0,"",SUM(K20:N20)) -> 1 | R20: =IF(P20="","",P20+Q20) -> 3 | S20: =IF(R20="","",IF(C20="Ecuador",R20,0)) -> 0 | T20: =IF(R20="","",R20-S20) -> 3 | U20: =IF(R20="","",IF(O20>R20,"Revisar: discapacidad "&O20&" mayor que el total "&R20,IF(OR(A20="",B20="",C20="",F20=""),"Falta año, mes, país o motivo",IF(AND(C20="Ecuador",E20=""),"Falta la ciudad","OK")))) -> OK
A21: 2025 | B21: Julio | C21: Ecuador | D21: =IF(E21="","",IFERROR(VLOOKUP(E21,'_Catalogos'!$J$2:$K$1000,2,FALSE),"")) -> Pichincha | E21: Quito | F21: Evento | H21: 1 | J21: 1 | L21: 3 | P21: =IF(COUNT(G21:O21)=0,"",SUM(G21:J21)) -> 2 | Q21: =IF(COUNT(G21:O21)=0,"",SUM(K21:N21)) -> 3 | R21: =IF(P21="","",P21+Q21) -> 5 | S21: =IF(R21="","",IF(C21="Ecuador",R21,0)) -> 5 | T21: =IF(R21="","",R21-S21) -> 0 | U21: =IF(R21="","",IF(O21>R21,"Revisar: discapacidad "&O21&" mayor que el total "&R21,IF(OR(A21="",B21="",C21="",F21=""),"Falta año, mes, país o motivo",IF(AND(C21="Ecuador",E21=""),"Falta la ciudad","OK")))) -> OK
A22: 2025 | B22: Julio | C22: Perú | D22: =IF(E22="","",IFERROR(VLOOKUP(E22,'_Catalogos'!$J$2:$K$1000,2,FALSE),"")) | F22: Turismo | G22: 3 | H22: 1 | J22: 1 | K22: 2 | L22: 2 | M22: 4 | P22: =IF(COUNT(G22:O22)=0,"",SUM(G22:J22)) -> 5 | Q22: =IF(COUNT(G22:O22)=0,"",SUM(K22:N22)) -> 8 | R22: =IF(P22="","",P22+Q22) -> 13 | S22: =IF(R22="","",IF(C22="Ecuador",R22,0)) -> 0 | T22: =IF(R22="","",R22-S22) -> 13 | U22: =IF(R22="","",IF(O22>R22,"Revisar: discapacidad "&O22&" mayor que el total "&R22,IF(OR(A22="",B22="",C22="",F22=""),"Falta año, mes, país o motivo",IF(AND(C22="Ecuador",E22=""),"Falta la ciudad","OK")))) -> OK
A23: 2025 | B23: Agosto | C23: Ecuador | D23: =IF(E23="","",IFERROR(VLOOKUP(E23,'_Catalogos'!$J$2:$K$1000,2,FALSE),"")) -> Tungurahua | E23: Ambato | F23: Turismo | G23: 5 | H23: 3 | K23: 2 | L23: 2 | M23: 1 | N23: 1 | P23: =IF(COUNT(G23:O23)=0,"",SUM(G23:J23)) -> 8 | Q23: =IF(COUNT(G23:O23)=0,"",SUM(K23:N23)) -> 6 | R23: =IF(P23="","",P23+Q23) -> 14 | S23: =IF(R23="","",IF(C23="Ecuador",R23,0)) -> 14 | T23: =IF(R23="","",R23-S23) -> 0 | U23: =IF(R23="","",IF(O23>R23,"Revisar: discapacidad "&O23&" mayor que el total "&R23,IF(OR(A23="",B23="",C23="",F23=""),"Falta año, mes, país o motivo",IF(AND(C23="Ecuador",E23=""),"Falta la ciudad","OK")))) -> OK
A24: 2025 | B24: Agosto | C24: Ecuador | D24: =IF(E24="","",IFERROR(VLOOKUP(E24,'_Catalogos'!$J$2:$K$1000,2,FALSE),"")) -> Tungurahua | E24: Pelileo | F24: Gastronomía | G24: 2 | H24: 2 | I24: 1 | K24: 5 | L24: 2 | P24: =IF(COUNT(G24:O24)=0,"",SUM(G24:J24)) -> 5 | Q24: =IF(COUNT(G24:O24)=0,"",SUM(K24:N24)) -> 7 | R24: =IF(P24="","",P24+Q24) -> 12 | S24: =IF(R24="","",IF(C24="Ecuador",R24,0)) -> 12 | T24: =IF(R24="","",R24-S24) -> 0 | U24: =IF(R24="","",IF(O24>R24,"Revisar: discapacidad "&O24&" mayor que el total "&R24,IF(OR(A24="",B24="",C24="",F24=""),"Falta año, mes, país o motivo",IF(AND(C24="Ecuador",E24=""),"Falta la ciudad","OK")))) -> OK
A25: 2025 | B25: Agosto | C25: Ecuador | D25: =IF(E25="","",IFERROR(VLOOKUP(E25,'_Catalogos'!$J$2:$K$1000,2,FALSE),"")) -> Cotopaxi | E25: Salcedo | F25: Gastronomía | H25: 2 | I25: 1 | K25: 3 | L25: 1 | N25: 1 | P25: =IF(COUNT(G25:O25)=0,"",SUM(G25:J25)) -> 3 | Q25: =IF(COUNT(G25:O25)=0,"",SUM(K25:N25)) -> 5 | R25: =IF(P25="","",P25+Q25) -> 8 | S25: =IF(R25="","",IF(C25="Ecuador",R25,0)) -> 8 | T25: =IF(R25="","",R25-S25) -> 0 | U25: =IF(R25="","",IF(O25>R25,"Revisar: discapacidad "&O25&" mayor que el total "&R25,IF(OR(A25="",B25="",C25="",F25=""),"Falta año, mes, país o motivo",IF(AND(C25="Ecuador",E25=""),"Falta la ciudad","OK")))) -> OK
A26: 2025 | B26: Agosto | C26: Argentina | D26: =IF(E26="","",IFERROR(VLOOKUP(E26,'_Catalogos'!$J$2:$K$1000,2,FALSE),"")) | F26: Turismo | H26: 1 | I26: 1 | L26: 1 | N26: 1 | O26: 4 | P26: =IF(COUNT(G26:O26)=0,"",SUM(G26:J26)) -> 2 | Q26: =IF(COUNT(G26:O26)=0,"",SUM(K26:N26)) -> 2 | R26: =IF(P26="","",P26+Q26) -> 4 | S26: =IF(R26="","",IF(C26="Ecuador",R26,0)) -> 0 | T26: =IF(R26="","",R26-S26) -> 4 | U26: =IF(R26="","",IF(O26>R26,"Revisar: discapacidad "&O26&" mayor que el total "&R26,IF(OR(A26="",B26="",C26="",F26=""),"Falta año, mes, país o motivo",IF(AND(C26="Ecuador",E26=""),"Falta la ciudad","OK")))) -> OK
A27: 2025 | B27: Septiembre | C27: Ecuador | D27: =IF(E27="","",IFERROR(VLOOKUP(E27,'_Catalogos'!$J$2:$K$1000,2,FALSE),"")) -> Loja | E27: Loja | F27: Evento | H27: 1 | I27: 1 | L27: 2 | N27: 1 | P27: =IF(COUNT(G27:O27)=0,"",SUM(G27:J27)) -> 2 | Q27: =IF(COUNT(G27:O27)=0,"",SUM(K27:N27)) -> 3 | R27: =IF(P27="","",P27+Q27) -> 5 | S27: =IF(R27="","",IF(C27="Ecuador",R27,0)) -> 5 | T27: =IF(R27="","",R27-S27) -> 0 | U27: =IF(R27="","",IF(O27>R27,"Revisar: discapacidad "&O27&" mayor que el total "&R27,IF(OR(A27="",B27="",C27="",F27=""),"Falta año, mes, país o motivo",IF(AND(C27="Ecuador",E27=""),"Falta la ciudad","OK")))) -> OK
A28: 2025 | B28: Septiembre | C28: España | D28: =IF(E28="","",IFERROR(VLOOKUP(E28,'_Catalogos'!$J$2:$K$1000,2,FALSE),"")) | F28: Negocios | G28: 2 | H28: 2 | I28: 1 | J28: 1 | K28: 2 | L28: 1 | P28: =IF(COUNT(G28:O28)=0,"",SUM(G28:J28)) -> 6 | Q28: =IF(COUNT(G28:O28)=0,"",SUM(K28:N28)) -> 3 | R28: =IF(P28="","",P28+Q28) -> 9 | S28: =IF(R28="","",IF(C28="Ecuador",R28,0)) -> 0 | T28: =IF(R28="","",R28-S28) -> 9 | U28: =IF(R28="","",IF(O28>R28,"Revisar: discapacidad "&O28&" mayor que el total "&R28,IF(OR(A28="",B28="",C28="",F28=""),"Falta año, mes, país o motivo",IF(AND(C28="Ecuador",E28=""),"Falta la ciudad","OK")))) -> OK
A29: 2025 | B29: Octubre | C29: Ecuador | D29: =IF(E29="","",IFERROR(VLOOKUP(E29,'_Catalogos'!$J$2:$K$1000,2,FALSE),"")) -> Cotopaxi | E29: Latacunga | F29: Gastronomía | J29: 1 | L29: 1 | M29: 1 | P29: =IF(COUNT(G29:O29)=0,"",SUM(G29:J29)) -> 1 | Q29: =IF(COUNT(G29:O29)=0,"",SUM(K29:N29)) -> 2 | R29: =IF(P29="","",P29+Q29) -> 3 | S29: =IF(R29="","",IF(C29="Ecuador",R29,0)) -> 3 | T29: =IF(R29="","",R29-S29) -> 0 | U29: =IF(R29="","",IF(O29>R29,"Revisar: discapacidad "&O29&" mayor que el total "&R29,IF(OR(A29="",B29="",C29="",F29=""),"Falta año, mes, país o motivo",IF(AND(C29="Ecuador",E29=""),"Falta la ciudad","OK")))) -> OK
A30: 2025 | B30: Octubre | C30: Ecuador | D30: =IF(E30="","",IFERROR(VLOOKUP(E30,'_Catalogos'!$J$2:$K$1000,2,FALSE),"")) -> Tungurahua | E30: Ambato | F30: Evento | G30: 1 | P30: =IF(COUNT(G30:O30)=0,"",SUM(G30:J30)) -> 1 | Q30: =IF(COUNT(G30:O30)=0,"",SUM(K30:N30)) -> 0 | R30: =IF(P30="","",P30+Q30) -> 1 | S30: =IF(R30="","",IF(C30="Ecuador",R30,0)) -> 1 | T30: =IF(R30="","",R30-S30) -> 0 | U30: =IF(R30="","",IF(O30>R30,"Revisar: discapacidad "&O30&" mayor que el total "&R30,IF(OR(A30="",B30="",C30="",F30=""),"Falta año, mes, país o motivo",IF(AND(C30="Ecuador",E30=""),"Falta la ciudad","OK")))) -> OK
A31: 2025 | B31: Octubre | C31: Chile | D31: =IF(E31="","",IFERROR(VLOOKUP(E31,'_Catalogos'!$J$2:$K$1000,2,FALSE),"")) | F31: Descanso | G31: 1 | H31: 2 | K31: 2 | L31: 1 | M31: 4 | P31: =IF(COUNT(G31:O31)=0,"",SUM(G31:J31)) -> 3 | Q31: =IF(COUNT(G31:O31)=0,"",SUM(K31:N31)) -> 7 | R31: =IF(P31="","",P31+Q31) -> 10 | S31: =IF(R31="","",IF(C31="Ecuador",R31,0)) -> 0 | T31: =IF(R31="","",R31-S31) -> 10 | U31: =IF(R31="","",IF(O31>R31,"Revisar: discapacidad "&O31&" mayor que el total "&R31,IF(OR(A31="",B31="",C31="",F31=""),"Falta año, mes, país o motivo",IF(AND(C31="Ecuador",E31=""),"Falta la ciudad","OK")))) -> OK
A32: 2025 | B32: Octubre | C32: Ecuador | D32: =IF(E32="","",IFERROR(VLOOKUP(E32,'_Catalogos'!$J$2:$K$1000,2,FALSE),"")) -> Tungurahua | E32: Pelileo | F32: Evento | H32: 1 | I32: 1 | J32: 1 | K32: 3 | L32: 1 | P32: =IF(COUNT(G32:O32)=0,"",SUM(G32:J32)) -> 3 | Q32: =IF(COUNT(G32:O32)=0,"",SUM(K32:N32)) -> 4 | R32: =IF(P32="","",P32+Q32) -> 7 | S32: =IF(R32="","",IF(C32="Ecuador",R32,0)) -> 7 | T32: =IF(R32="","",R32-S32) -> 0 | U32: =IF(R32="","",IF(O32>R32,"Revisar: discapacidad "&O32&" mayor que el total "&R32,IF(OR(A32="",B32="",C32="",F32=""),"Falta año, mes, país o motivo",IF(AND(C32="Ecuador",E32=""),"Falta la ciudad","OK")))) -> OK
A33: 2025 | B33: Noviembre | C33: Ecuador | D33: =IF(E33="","",IFERROR(VLOOKUP(E33,'_Catalogos'!$J$2:$K$1000,2,FALSE),"")) -> Pastaza | E33: Puyo | F33: Gastronomía | G33: 1 | H33: 1 | I33: 2 | J33: 1 | K33: 2 | L33: 2 | M33: 1 | P33: =IF(COUNT(G33:O33)=0,"",SUM(G33:J33)) -> 5 | Q33: =IF(COUNT(G33:O33)=0,"",SUM(K33:N33)) -> 5 | R33: =IF(P33="","",P33+Q33) -> 10 | S33: =IF(R33="","",IF(C33="Ecuador",R33,0)) -> 10 | T33: =IF(R33="","",R33-S33) -> 0 | U33: =IF(R33="","",IF(O33>R33,"Revisar: discapacidad "&O33&" mayor que el total "&R33,IF(OR(A33="",B33="",C33="",F33=""),"Falta año, mes, país o motivo",IF(AND(C33="Ecuador",E33=""),"Falta la ciudad","OK")))) -> OK
A34: 2025 | B34: Noviembre | C34: Mauricio | D34: =IF(E34="","",IFERROR(VLOOKUP(E34,'_Catalogos'!$J$2:$K$1000,2,FALSE),"")) | F34: Evento | G34: 1 | L34: 2 | M34: 1 | P34: =IF(COUNT(G34:O34)=0,"",SUM(G34:J34)) -> 1 | Q34: =IF(COUNT(G34:O34)=0,"",SUM(K34:N34)) -> 3 | R34: =IF(P34="","",P34+Q34) -> 4 | S34: =IF(R34="","",IF(C34="Ecuador",R34,0)) -> 0 | T34: =IF(R34="","",R34-S34) -> 4 | U34: =IF(R34="","",IF(O34>R34,"Revisar: discapacidad "&O34&" mayor que el total "&R34,IF(OR(A34="",B34="",C34="",F34=""),"Falta año, mes, país o motivo",IF(AND(C34="Ecuador",E34=""),"Falta la ciudad","OK")))) -> OK
A35: 2025 | B35: Noviembre | C35: Ecuador | D35: =IF(E35="","",IFERROR(VLOOKUP(E35,'_Catalogos'!$J$2:$K$1000,2,FALSE),"")) -> Loja | E35: Loja | F35: Gastronomía | G35: 1 | H35: 1 | I35: 1 | M35: 1 | P35: =IF(COUNT(G35:O35)=0,"",SUM(G35:J35)) -> 3 | Q35: =IF(COUNT(G35:O35)=0,"",SUM(K35:N35)) -> 1 | R35: =IF(P35="","",P35+Q35) -> 4 | S35: =IF(R35="","",IF(C35="Ecuador",R35,0)) -> 4 | T35: =IF(R35="","",R35-S35) -> 0 | U35: =IF(R35="","",IF(O35>R35,"Revisar: discapacidad "&O35&" mayor que el total "&R35,IF(OR(A35="",B35="",C35="",F35=""),"Falta año, mes, país o motivo",IF(AND(C35="Ecuador",E35=""),"Falta la ciudad","OK")))) -> OK
A36: 2025 | B36: Diciembre | C36: Ecuador | D36: =IF(E36="","",IFERROR(VLOOKUP(E36,'_Catalogos'!$J$2:$K$1000,2,FALSE),"")) -> Tungurahua | E36: Ambato | F36: Turismo | G36: 4 | H36: 2 | J36: 1 | K36: 3 | M36: 2 | N36: 1 | P36: =IF(COUNT(G36:O36)=0,"",SUM(G36:J36)) -> 7 | Q36: =IF(COUNT(G36:O36)=0,"",SUM(K36:N36)) -> 6 | R36: =IF(P36="","",P36+Q36) -> 13 | S36: =IF(R36="","",IF(C36="Ecuador",R36,0)) -> 13 | T36: =IF(R36="","",R36-S36) -> 0 | U36: =IF(R36="","",IF(O36>R36,"Revisar: discapacidad "&O36&" mayor que el total "&R36,IF(OR(A36="",B36="",C36="",F36=""),"Falta año, mes, país o motivo",IF(AND(C36="Ecuador",E36=""),"Falta la ciudad","OK")))) -> OK
A37: 2025 | B37: Diciembre | C37: Ecuador | D37: =IF(E37="","",IFERROR(VLOOKUP(E37,'_Catalogos'!$J$2:$K$1000,2,FALSE),"")) -> Pichincha | E37: Quito | F37: Turismo | G37: 2 | H37: 3 | I37: 2 | J37: 2 | K37: 2 | L37: 4 | P37: =IF(COUNT(G37:O37)=0,"",SUM(G37:J37)) -> 9 | Q37: =IF(COUNT(G37:O37)=0,"",SUM(K37:N37)) -> 6 | R37: =IF(P37="","",P37+Q37) -> 15 | S37: =IF(R37="","",IF(C37="Ecuador",R37,0)) -> 15 | T37: =IF(R37="","",R37-S37) -> 0 | U37: =IF(R37="","",IF(O37>R37,"Revisar: discapacidad "&O37&" mayor que el total "&R37,IF(OR(A37="",B37="",C37="",F37=""),"Falta año, mes, país o motivo",IF(AND(C37="Ecuador",E37=""),"Falta la ciudad","OK")))) -> OK
A38: 2025 | B38: Diciembre | C38: Brasil | D38: =IF(E38="","",IFERROR(VLOOKUP(E38,'_Catalogos'!$J$2:$K$1000,2,FALSE),"")) | F38: Turismo | G38: 1 | H38: 3 | I38: 1 | L38: 2 | M38: 1 | P38: =IF(COUNT(G38:O38)=0,"",SUM(G38:J38)) -> 5 | Q38: =IF(COUNT(G38:O38)=0,"",SUM(K38:N38)) -> 3 | R38: =IF(P38="","",P38+Q38) -> 8 | S38: =IF(R38="","",IF(C38="Ecuador",R38,0)) -> 0 | T38: =IF(R38="","",R38-S38) -> 8 | U38: =IF(R38="","",IF(O38>R38,"Revisar: discapacidad "&O38&" mayor que el total "&R38,IF(OR(A38="",B38="",C38="",F38=""),"Falta año, mes, país o motivo",IF(AND(C38="Ecuador",E38=""),"Falta la ciudad","OK")))) -> OK
A39: 2025 | B39: Diciembre | C39: Ecuador | D39: =IF(E39="","",IFERROR(VLOOKUP(E39,'_Catalogos'!$J$2:$K$1000,2,FALSE),"")) -> Napo | E39: Tena | F39: Turismo | G39: 3 | H39: 5 | I39: 1 | K39: 4 | L39: 3 | M39: 1 | N39: 2 | P39: =IF(COUNT(G39:O39)=0,"",SUM(G39:J39)) -> 9 | Q39: =IF(COUNT(G39:O39)=0,"",SUM(K39:N39)) -> 10 | R39: =IF(P39="","",P39+Q39) -> 19 | S39: =IF(R39="","",IF(C39="Ecuador",R39,0)) -> 19 | T39: =IF(R39="","",R39-S39) -> 0 | U39: =IF(R39="","",IF(O39>R39,"Revisar: discapacidad "&O39&" mayor que el total "&R39,IF(OR(A39="",B39="",C39="",F39=""),"Falta año, mes, país o motivo",IF(AND(C39="Ecuador",E39=""),"Falta la ciudad","OK")))) -> OK
A40: 2025 | B40: Diciembre | C40: Ecuador | D40: =IF(E40="","",IFERROR(VLOOKUP(E40,'_Catalogos'!$J$2:$K$1000,2,FALSE),"")) -> Galápagos | E40: Puerto Villamil | F40: Turismo | G40: 1 | H40: 2 | K40: 2 | L40: 1 | M40: 1 | N40: 4 | P40: =IF(COUNT(G40:O40)=0,"",SUM(G40:J40)) -> 3 | Q40: =IF(COUNT(G40:O40)=0,"",SUM(K40:N40)) -> 8 | R40: =IF(P40="","",P40+Q40) -> 11 | S40: =IF(R40="","",IF(C40="Ecuador",R40,0)) -> 11 | T40: =IF(R40="","",R40-S40) -> 0 | U40: =IF(R40="","",IF(O40>R40,"Revisar: discapacidad "&O40&" mayor que el total "&R40,IF(OR(A40="",B40="",C40="",F40=""),"Falta año, mes, país o motivo",IF(AND(C40="Ecuador",E40=""),"Falta la ciudad","OK")))) -> OK
...

Sheet Hacienda La Colina
A1: Año | B1: Mes | C1: País | D1: Provincia | E1: Ciudad | F1: Motivo de visita | G1: Mujeres 0-30 | H1: Mujeres 31-45 | I1: Mujeres 46-60 | J1: Mujeres 61+ | K1: Hombres 0-30 | L1: Hombres 31-45 | M1: Hombres 46-60 | N1: Hombres 61+ | O1: Personas con discapacidad | P1: Total mujeres | Q1: Total hombres | R1: Total visitantes | S1: Nacionales | T1: Extranjeros | U1: Estado
A2: 2025 | B2: Enero | C2: Ecuador | D2: =IF(E2="","",IFERROR(VLOOKUP(E2,'_Catalogos'!$J$2:$K$1000,2,FALSE),"")) -> Loja | E2: Loja | F2: Descanso | G2: 4 | H2: 3 | I2: 2 | K2: 1 | L2: 3 | M2: 1 | P2: =IF(COUNT(G2:O2)=0,"",SUM(G2:J2)) -> 9 | Q2: =IF(COUNT(G2:O2)=0,"",SUM(K2:N2)) -> 5 | R2: =IF(P2="","",P2+Q2) -> 14 | S2: =IF(R2="","",IF(C2="Ecuador",R2,0)) -> 14 | T2: =IF(R2="","",R2-S2) -> 0 | U2: =IF(R2="","",IF(O2>R2,"Revisar: discapacidad "&O2&" mayor que el total "&R2,IF(OR(A2="",B2="",C2="",F2=""),"Falta año, mes, país o motivo",IF(AND(C2="Ecuador",E2=""),"Falta la ciudad","OK")))) -> OK
A3: 2025 | B3: Enero | C3: Argentina | D3: =IF(E3="","",IFERROR(VLOOKUP(E3,'_Catalogos'!$J$2:$K$1000,2,FALSE),"")) | F3: Visita familiar | G3: 3 | H3: 1 | I3: 2 | K3: 1 | L3: 3 | M3: 2 | P3: =IF(COUNT(G3:O3)=0,"",SUM(G3:J3)) -> 6 | Q3: =IF(COUNT(G3:O3)=0,"",SUM(K3:N3)) -> 6 | R3: =IF(P3="","",P3+Q3) -> 12 | S3: =IF(R3="","",IF(C3="Ecuador",R3,0)) -> 0 | T3: =IF(R3="","",R3-S3) -> 12 | U3: =IF(R3="","",IF(O3>R3,"Revisar: discapacidad "&O3&" mayor que el total "&R3,IF(OR(A3="",B3="",C3="",F3=""),"Falta año, mes, país o motivo",IF(AND(C3="Ecuador",E3=""),"Falta la ciudad","OK")))) -> OK
A4: 2025 | B4: Enero | C4: Ecuador | D4: =IF(E4="","",IFERROR(VLOOKUP(E4,'_Catalogos'!$J$2:$K$1000,2,FALSE),"")) -> Cotopaxi | E4: Salcedo | F4: Visita familiar | H4: 3 | I4: 1 | K4: 3 | L4: 3 | M4: 2 | O4: 2 | P4: =IF(COUNT(G4:O4)=0,"",SUM(G4:J4)) -> 4 | Q4: =IF(COUNT(G4:O4)=0,"",SUM(K4:N4)) -> 8 | R4: =IF(P4="","",P4+Q4) -> 12 | S4: =IF(R4="","",IF(C4="Ecuador",R4,0)) -> 12 | T4: =IF(R4="","",R4-S4) -> 0 | U4: =IF(R4="","",IF(O4>R4,"Revisar: discapacidad "&O4&" mayor que el total "&R4,IF(OR(A4="",B4="",C4="",F4=""),"Falta año, mes, país o motivo",IF(AND(C4="Ecuador",E4=""),"Falta la ciudad","OK")))) -> OK
A5: 2025 | B5: Enero | C5: Ecuador | D5: =IF(E5="","",IFERROR(VLOOKUP(E5,'_Catalogos'!$J$2:$K$1000,2,FALSE),"")) -> El Oro | E5: Machala | F5: Turismo | G5: 4 | H5: 1 | I5: 1 | J5: 1 | K5: 2 | L5: 1 | M5: 1 | P5: =IF(COUNT(G5:O5)=0,"",SUM(G5:J5)) -> 7 | Q5: =IF(COUNT(G5:O5)=0,"",SUM(K5:N5)) -> 4 | R5: =IF(P5="","",P5+Q5) -> 11 | S5: =IF(R5="","",IF(C5="Ecuador",R5,0)) -> 11 | T5: =IF(R5="","",R5-S5) -> 0 | U5: =IF(R5="","",IF(O5>R5,"Revisar: discapacidad "&O5&" mayor que el total "&R5,IF(OR(A5="",B5="",C5="",F5=""),"Falta año, mes, país o motivo",IF(AND(C5="Ecuador",E5=""),"Falta la ciudad","OK")))) -> OK
A6: 2025 | B6: Enero | C6: Ecuador | D6: =IF(E6="","",IFERROR(VLOOKUP(E6,'_Catalogos'!$J$2:$K$1000,2,FALSE),"")) -> Loja | E6: Loja | F6: Turismo | G6: 2 | H6: 5 | I6: 2 | J6: 1 | K6: 1 | L6: 4 | M6: 2 | P6: =IF(COUNT(G6:O6)=0,"",SUM(G6:J6)) -> 10 | Q6: =IF(COUNT(G6:O6)=0,"",SUM(K6:N6)) -> 7 | R6: =IF(P6="","",P6+Q6) -> 17 | S6: =IF(R6="","",IF(C6="Ecuador",R6,0)) -> 17 | T6: =IF(R6="","",R6-S6) -> 0 | U6: =IF(R6="","",IF(O6>R6,"Revisar: discapacidad "&O6&" mayor que el total "&R6,IF(OR(A6="",B6="",C6="",F6=""),"Falta año, mes, país o motivo",IF(AND(C6="Ecuador",E6=""),"Falta la ciudad","OK")))) -> OK
A7: 2025 | B7: Enero | C7: Ecuador | D7: =IF(E7="","",IFERROR(VLOOKUP(E7,'_Catalogos'!$J$2:$K$1000,2,FALSE),"")) -> El Oro | E7: Balsas | F7: Gastronomía | G7: 3 | P7: =IF(COUNT(G7:O7)=0,"",SUM(G7:J7)) -> 3 | Q7: =IF(COUNT(G7:O7)=0,"",SUM(K7:N7)) -> 0 | R7: =IF(P7="","",P7+Q7) -> 3 | S7: =IF(R7="","",IF(C7="Ecuador",R7,0)) -> 3 | T7: =IF(R7="","",R7-S7) -> 0 | U7: =IF(R7="","",IF(O7>R7,"Revisar: discapacidad "&O7&" mayor que el total "&R7,IF(OR(A7="",B7="",C7="",F7=""),"Falta año, mes, país o motivo",IF(AND(C7="Ecuador",E7=""),"Falta la ciudad","OK")))) -> OK
A8: 2025 | B8: Febrero | C8: Estados Unidos | D8: =IF(E8="","",IFERROR(VLOOKUP(E8,'_Catalogos'!$J$2:$K$1000,2,FALSE),"")) | F8: Visita familiar | G8: 2 | H8: 2 | I8: 2 | K8: 1 | L8: 2 | M8: 2 | P8: =IF(COUNT(G8:O8)=0,"",SUM(G8:J8)) -> 6 | Q8: =IF(COUNT(G8:O8)=0,"",SUM(K8:N8)) -> 5 | R8: =IF(P8="","",P8+Q8) -> 11 | S8: =IF(R8="","",IF(C8="Ecuador",R8,0)) -> 0 | T8: =IF(R8="","",R8-S8) -> 11 | U8: =IF(R8="","",IF(O8>R8,"Revisar: discapacidad "&O8&" mayor que el total "&R8,IF(OR(A8="",B8="",C8="",F8=""),"Falta año, mes, país o motivo",IF(AND(C8="Ecuador",E8=""),"Falta la ciudad","OK")))) -> OK
A9: 2025 | B9: Febrero | C9: Colombia | D9: =IF(E9="","",IFERROR(VLOOKUP(E9,'_Catalogos'!$J$2:$K$1000,2,FALSE),"")) | F9: Evento | G9: 1 | H9: 2 | I9: 4 | J9: 1 | L9: 2 | M9: 3 | P9: =IF(COUNT(G9:O9)=0,"",SUM(G9:J9)) -> 8 | Q9: =IF(COUNT(G9:O9)=0,"",SUM(K9:N9)) -> 5 | R9: =IF(P9="","",P9+Q9) -> 13 | S9: =IF(R9="","",IF(C9="Ecuador",R9,0)) -> 0 | T9: =IF(R9="","",R9-S9) -> 13 | U9: =IF(R9="","",IF(O9>R9,"Revisar: discapacidad "&O9&" mayor que el total "&R9,IF(OR(A9="",B9="",C9="",F9=""),"Falta año, mes, país o motivo",IF(AND(C9="Ecuador",E9=""),"Falta la ciudad","OK")))) -> OK
A10: 2025 | B10: Febrero | C10: Ecuador | D10: =IF(E10="","",IFERROR(VLOOKUP(E10,'_Catalogos'!$J$2:$K$1000,2,FALSE),"")) -> Loja | E10: Loja | F10: Turismo | H10: 1 | I10: 3 | K10: 1 | L10: 1 | N10: 1 | P10: =IF(COUNT(G10:O10)=0,"",SUM(G10:J10)) -> 4 | Q10: =IF(COUNT(G10:O10)=0,"",SUM(K10:N10)) -> 3 | R10: =IF(P10="","",P10+Q10) -> 7 | S10: =IF(R10="","",IF(C10="Ecuador",R10,0)) -> 7 | T10: =IF(R10="","",R10-S10) -> 0 | U10: =IF(R10="","",IF(O10>R10,"Revisar: discapacidad "&O10&" mayor que el total "&R10,IF(OR(A10="",B10="",C10="",F10=""),"Falta año, mes, país o motivo",IF(AND(C10="Ecuador",E10=""),"Falta la ciudad","OK")))) -> OK
A11: 2025 | B11: Febrero | C11: Ecuador | D11: =IF(E11="","",IFERROR(VLOOKUP(E11,'_Catalogos'!$J$2:$K$1000,2,FALSE),"")) -> Tungurahua | E11: Baños | F11: Evento | G11: 1 | H11: 1 | I11: 1 | K11: 2 | L11: 3 | M11: 2 | N11: 1 | P11: =IF(COUNT(G11:O11)=0,"",SUM(G11:J11)) -> 3 | Q11: =IF(COUNT(G11:O11)=0,"",SUM(K11:N11)) -> 8 | R11: =IF(P11="","",P11+Q11) -> 11 | S11: =IF(R11="","",IF(C11="Ecuador",R11,0)) -> 11 | T11: =IF(R11="","",R11-S11) -> 0 | U11: =IF(R11="","",IF(O11>R11,"Revisar: discapacidad "&O11&" mayor que el total "&R11,IF(OR(A11="",B11="",C11="",F11=""),"Falta año, mes, país o motivo",IF(AND(C11="Ecuador",E11=""),"Falta la ciudad","OK")))) -> OK
A12: 2025 | B12: Marzo | C12: México | D12: =IF(E12="","",IFERROR(VLOOKUP(E12,'_Catalogos'!$J$2:$K$1000,2,FALSE),"")) | F12: Descanso | H12: 1 | J12: 1 | K12: 1 | M12: 2 | P12: =IF(COUNT(G12:O12)=0,"",SUM(G12:J12)) -> 2 | Q12: =IF(COUNT(G12:O12)=0,"",SUM(K12:N12)) -> 3 | R12: =IF(P12="","",P12+Q12) -> 5 | S12: =IF(R12="","",IF(C12="Ecuador",R12,0)) -> 0 | T12: =IF(R12="","",R12-S12) -> 5 | U12: =IF(R12="","",IF(O12>R12,"Revisar: discapacidad "&O12&" mayor que el total "&R12,IF(OR(A12="",B12="",C12="",F12=""),"Falta año, mes, país o motivo",IF(AND(C12="Ecuador",E12=""),"Falta la ciudad","OK")))) -> OK
A13: 2025 | B13: Marzo | C13: Colombia | D13: =IF(E13="","",IFERROR(VLOOKUP(E13,'_Catalogos'!$J$2:$K$1000,2,FALSE),"")) | F13: Turismo | H13: 2 | I13: 2 | K13: 2 | L13: 1 | M13: 4 | N13: 1 | P13: =IF(COUNT(G13:O13)=0,"",SUM(G13:J13)) -> 4 | Q13: =IF(COUNT(G13:O13)=0,"",SUM(K13:N13)) -> 8 | R13: =IF(P13="","",P13+Q13) -> 12 | S13: =IF(R13="","",IF(C13="Ecuador",R13,0)) -> 0 | T13: =IF(R13="","",R13-S13) -> 12 | U13: =IF(R13="","",IF(O13>R13,"Revisar: discapacidad "&O13&" mayor que el total "&R13,IF(OR(A13="",B13="",C13="",F13=""),"Falta año, mes, país o motivo",IF(AND(C13="Ecuador",E13=""),"Falta la ciudad","OK")))) -> OK
A14: 2025 | B14: Abril | C14: Francia | D14: =IF(E14="","",IFERROR(VLOOKUP(E14,'_Catalogos'!$J$2:$K$1000,2,FALSE),"")) | F14: Gastronomía | G14: 1 | M14: 1 | P14: =IF(COUNT(G14:O14)=0,"",SUM(G14:J14)) -> 1 | Q14: =IF(COUNT(G14:O14)=0,"",SUM(K14:N14)) -> 1 | R14: =IF(P14="","",P14+Q14) -> 2 | S14: =IF(R14="","",IF(C14="Ecuador",R14,0)) -> 0 | T14: =IF(R14="","",R14-S14) -> 2 | U14: =IF(R14="","",IF(O14>R14,"Revisar: discapacidad "&O14&" mayor que el total "&R14,IF(OR(A14="",B14="",C14="",F14=""),"Falta año, mes, país o motivo",IF(AND(C14="Ecuador",E14=""),"Falta la ciudad","OK")))) -> OK
A15: 2025 | B15: Abril | C15: Ecuador | D15: =IF(E15="","",IFERROR(VLOOKUP(E15,'_Catalogos'!$J$2:$K$1000,2,FALSE),"")) -> Chimborazo | E15: Riobamba | F15: Gastronomía | H15: 1 | K15: 2 | L15: 1 | M15: 1 | N15: 1 | P15: =IF(COUNT(G15:O15)=0,"",SUM(G15:J15)) -> 1 | Q15: =IF(COUNT(G15:O15)=0,"",SUM(K15:N15)) -> 5 | R15: =IF(P15="","",P15+Q15) -> 6 | S15: =IF(R15="","",IF(C15="Ecuador",R15,0)) -> 6 | T15: =IF(R15="","",R15-S15) -> 0 | U15: =IF(R15="","",IF(O15>R15,"Revisar: discapacidad "&O15&" mayor que el total "&R15,IF(OR(A15="",B15="",C15="",F15=""),"Falta año, mes, país o motivo",IF(AND(C15="Ecuador",E15=""),"Falta la ciudad","OK")))) -> OK
A16: 2025 | B16: Abril | C16: Ecuador | D16: =IF(E16="","",IFERROR(VLOOKUP(E16,'_Catalogos'!$J$2:$K$1000,2,FALSE),"")) -> Cotopaxi | E16: Latacunga | F16: Descanso | L16: 1 | P16: =IF(COUNT(G16:O16)=0,"",SUM(G16:J16)) -> 0 | Q16: =IF(COUNT(G16:O16)=0,"",SUM(K16:N16)) -> 1 | R16: =IF(P16="","",P16+Q16) -> 1 | S16: =IF(R16="","",IF(C16="Ecuador",R16,0)) -> 1 | T16: =IF(R16="","",R16-S16) -> 0 | U16: =IF(R16="","",IF(O16>R16,"Revisar: discapacidad "&O16&" mayor que el total "&R16,IF(OR(A16="",B16="",C16="",F16=""),"Falta año, mes, país o motivo",IF(AND(C16="Ecuador",E16=""),"Falta la ciudad","OK")))) -> OK
A17: 2025 | B17: Mayo | C17: Ecuador | D17: =IF(E17="","",IFERROR(VLOOKUP(E17,'_Catalogos'!$J$2:$K$1000,2,FALSE),"")) -> Imbabura | E17: Ibarra | F17: Gastronomía | G17: 2 | H17: 4 | I17: 2 | K17: 2 | L17: 1 | M17: 3 | N17: 2 | P17: =IF(COUNT(G17:O17)=0,"",SUM(G17:J17)) -> 8 | Q17: =IF(COUNT(G17:O17)=0,"",SUM(K17:N17)) -> 8 | R17: =IF(P17="","",P17+Q17) -> 16 | S17: =IF(R17="","",IF(C17="Ecuador",R17,0)) -> 16 | T17: =IF(R17="","",R17-S17) -> 0 | U17: =IF(R17="","",IF(O17>R17,"Revisar: discapacidad "&O17&" mayor que el total "&R17,IF(OR(A17="",B17="",C17="",F17=""),"Falta año, mes, país o motivo",IF(AND(C17="Ecuador",E17=""),"Falta la ciudad","OK")))) -> OK
A18: 2025 | B18: Mayo | C18: Argentina | D18: =IF(E18="","",IFERROR(VLOOKUP(E18,'_Catalogos'!$J$2:$K$1000,2,FALSE),"")) | F18: Turismo | G18: 1 | H18: 1 | J18: 1 | L18: 3 | M18: 1 | P18: =IF(COUNT(G18:O18)=0,"",SUM(G18:J18)) -> 3 | Q18: =IF(COUNT(G18:O18)=0,"",SUM(K18:N18)) -> 4 | R18: =IF(P18="","",P18+Q18) -> 7 | S18: =IF(R18="","",IF(C18="Ecuador",R18,0)) -> 0 | T18: =IF(R18="","",R18-S18) -> 7 | U18: =IF(R18="","",IF(O18>R18,"Revisar: discapacidad "&O18&" mayor que el total "&R18,IF(OR(A18="",B18="",C18="",F18=""),"Falta año, mes, país o motivo",IF(AND(C18="Ecuador",E18=""),"Falta la ciudad","OK")))) -> OK
A19: 2025 | B19: Junio | C19: Ecuador | D19: =IF(E19="","",IFERROR(VLOOKUP(E19,'_Catalogos'!$J$2:$K$1000,2,FALSE),"")) -> Loja | E19: Loja | F19: Descanso | G19: 2 | H19: 3 | I19: 1 | K19: 1 | M19: 3 | N19: 1 | P19: =IF(COUNT(G19:O19)=0,"",SUM(G19:J19)) -> 6 | Q19: =IF(COUNT(G19:O19)=0,"",SUM(K19:N19)) -> 5 | R19: =IF(P19="","",P19+Q19) -> 11 | S19: =IF(R19="","",IF(C19="Ecuador",R19,0)) -> 11 | T19: =IF(R19="","",R19-S19) -> 0 | U19: =IF(R19="","",IF(O19>R19,"Revisar: discapacidad "&O19&" mayor que el total "&R19,IF(OR(A19="",B19="",C19="",F19=""),"Falta año, mes, país o motivo",IF(AND(C19="Ecuador",E19=""),"Falta la ciudad","OK")))) -> OK
A20: 2025 | B20: Junio | C20: Ecuador | D20: =IF(E20="","",IFERROR(VLOOKUP(E20,'_Catalogos'!$J$2:$K$1000,2,FALSE),"")) -> Tungurahua | E20: Baños | F20: Turismo | J20: 1 | L20: 1 | N20: 1 | P20: =IF(COUNT(G20:O20)=0,"",SUM(G20:J20)) -> 1 | Q20: =IF(COUNT(G20:O20)=0,"",SUM(K20:N20)) -> 2 | R20: =IF(P20="","",P20+Q20) -> 3 | S20: =IF(R20="","",IF(C20="Ecuador",R20,0)) -> 3 | T20: =IF(R20="","",R20-S20) -> 0 | U20: =IF(R20="","",IF(O20>R20,"Revisar: discapacidad "&O20&" mayor que el total "&R20,IF(OR(A20="",B20="",C20="",F20=""),"Falta año, mes, país o motivo",IF(AND(C20="Ecuador",E20=""),"Falta la ciudad","OK")))) -> OK
A21: 2025 | B21: Junio | C21: Ecuador | D21: =IF(E21="","",IFERROR(VLOOKUP(E21,'_Catalogos'!$J$2:$K$1000,2,FALSE),"")) -> Imbabura | E21: Ibarra | F21: Turismo | H21: 1 | I21: 1 | J21: 2 | K21: 2 | L21: 1 | O21: 7 | P21: =IF(COUNT(G21:O21)=0,"",SUM(G21:J21)) -> 4 | Q21: =IF(COUNT(G21:O21)=0,"",SUM(K21:N21)) -> 3 | R21: =IF(P21="","",P21+Q21) -> 7 | S21: =IF(R21="","",IF(C21="Ecuador",R21,0)) -> 7 | T21: =IF(R21="","",R21-S21) -> 0 | U21: =IF(R21="","",IF(O21>R21,"Revisar: discapacidad "&O21&" mayor que el total "&R21,IF(OR(A21="",B21="",C21="",F21=""),"Falta año, mes, país o motivo",IF(AND(C21="Ecuador",E21=""),"Falta la ciudad","OK")))) -> OK
A22: 2025 | B22: Julio | C22: Perú | D22: =IF(E22="","",IFERROR(VLOOKUP(E22,'_Catalogos'!$J$2:$K$1000,2,FALSE),"")) | F22: Turismo | H22: 1 | I22: 1 | K22: 1 | N22: 1 | P22: =IF(COUNT(G22:O22)=0,"",SUM(G22:J22)) -> 2 | Q22: =IF(COUNT(G22:O22)=0,"",SUM(K22:N22)) -> 2 | R22: =IF(P22="","",P22+Q22) -> 4 | S22: =IF(R22="","",IF(C22="Ecuador",R22,0)) -> 0 | T22: =IF(R22="","",R22-S22) -> 4 | U22: =IF(R22="","",IF(O22>R22,"Revisar: discapacidad "&O22&" mayor que el total "&R22,IF(OR(A22="",B22="",C22="",F22=""),"Falta año, mes, país o motivo",IF(AND(C22="Ecuador",E22=""),"Falta la ciudad","OK")))) -> OK
A23: 2025 | B23: Julio | C23: Colombia | D23: =IF(E23="","",IFERROR(VLOOKUP(E23,'_Catalogos'!$J$2:$K$1000,2,FALSE),"")) | F23: Descanso | G23: 1 | H23: 3 | K23: 1 | L23: 2 | M23: 1 | N23: 1 | P23: =IF(COUNT(G23:O23)=0,"",SUM(G23:J23)) -> 4 | Q23: =IF(COUNT(G23:O23)=0,"",SUM(K23:N23)) -> 5 | R23: =IF(P23="","",P23+Q23) -> 9 | S23: =IF(R23="","",IF(C23="Ecuador",R23,0)) -> 0 | T23: =IF(R23="","",R23-S23) -> 9 | U23: =IF(R23="","",IF(O23>R23,"Revisar: discapacidad "&O23&" mayor que el total "&R23,IF(OR(A23="",B23="",C23="",F23=""),"Falta año, mes, país o motivo",IF(AND(C23="Ecuador",E23=""),"Falta la ciudad","OK")))) -> OK
A24: 2025 | B24: Julio | C24: Ecuador | D24: =IF(E24="","",IFERROR(VLOOKUP(E24,'_Catalogos'!$J$2:$K$1000,2,FALSE),"")) -> Guayas | E24: Guayaquil | F24: Evento | G24: 2 | H24: 4 | I24: 1 | J24: 2 | K24: 3 | L24: 1 | M24: 1 | P24: =IF(COUNT(G24:O24)=0,"",SUM(G24:J24)) -> 9 | Q24: =IF(COUNT(G24:O24)=0,"",SUM(K24:N24)) -> 5 | R24: =IF(P24="","",P24+Q24) -> 14 | S24: =IF(R24="","",IF(C24="Ecuador",R24,0)) -> 14 | T24: =IF(R24="","",R24-S24) -> 0 | U24: =IF(R24="","",IF(O24>R24,"Revisar: discapacidad "&O24&" mayor que el total "&R24,IF(OR(A24="",B24="",C24="",F24=""),"Falta año, mes, país o motivo",IF(AND(C24="Ecuador",E24=""),"Falta la ciudad","OK")))) -> OK
A25: 2025 | B25: Agosto | C25: Ecuador | D25: =IF(E25="","",IFERROR(VLOOKUP(E25,'_Catalogos'!$J$2:$K$1000,2,FALSE),"")) -> Napo | E25: Tena | F25: Turismo | G25: 5 | H25: 3 | I25: 2 | J25: 1 | K25: 4 | L25: 6 | M25: 2 | P25: =IF(COUNT(G25:O25)=0,"",SUM(G25:J25)) -> 11 | Q25: =IF(COUNT(G25:O25)=0,"",SUM(K25:N25)) -> 12 | R25: =IF(P25="","",P25+Q25) -> 23 | S25: =IF(R25="","",IF(C25="Ecuador",R25,0)) -> 23 | T25: =IF(R25="","",R25-S25) -> 0 | U25: =IF(R25="","",IF(O25>R25,"Revisar: discapacidad "&O25&" mayor que el total "&R25,IF(OR(A25="",B25="",C25="",F25=""),"Falta año, mes, país o motivo",IF(AND(C25="Ecuador",E25=""),"Falta la ciudad","OK")))) -> OK
A26: 2025 | B26: Agosto | C26: Ecuador | D26: =IF(E26="","",IFERROR(VLOOKUP(E26,'_Catalogos'!$J$2:$K$1000,2,FALSE),"")) -> Tungurahua | E26: Ambato | F26: Visita familiar | G26: 3 | H26: 3 | I26: 1 | J26: 1 | K26: 2 | L26: 1 | M26: 1 | O26: 8 | P26: =IF(COUNT(G26:O26)=0,"",SUM(G26:J26)) -> 8 | Q26: =IF(COUNT(G26:O26)=0,"",SUM(K26:N26)) -> 4 | R26: =IF(P26="","",P26+Q26) -> 12 | S26: =IF(R26="","",IF(C26="Ecuador",R26,0)) -> 12 | T26: =IF(R26="","",R26-S26) -> 0 | U26: =IF(R26="","",IF(O26>R26,"Revisar: discapacidad "&O26&" mayor que el total "&R26,IF(OR(A26="",B26="",C26="",F26=""),"Falta año, mes, país o motivo",IF(AND(C26="Ecuador",E26=""),"Falta la ciudad","OK")))) -> OK
A27: 2025 | B27: Agosto | C27: Ecuador | D27: =IF(E27="","",IFERROR(VLOOKUP(E27,'_Catalogos'!$J$2:$K$1000,2,FALSE),"")) -> Carchi | E27: Tulcán | F27: Descanso | G27: 4 | H27: 1 | I27: 6 | J27: 1 | K27: 3 | L27: 1 | M27: 1 | N27: 2 | P27: =IF(COUNT(G27:O27)=0,"",SUM(G27:J27)) -> 12 | Q27: =IF(COUNT(G27:O27)=0,"",SUM(K27:N27)) -> 7 | R27: =IF(P27="","",P27+Q27) -> 19 | S27: =IF(R27="","",IF(C27="Ecuador",R27,0)) -> 19 | T27: =IF(R27="","",R27-S27) -> 0 | U27: =IF(R27="","",IF(O27>R27,"Revisar: discapacidad "&O27&" mayor que el total "&R27,IF(OR(A27="",B27="",C27="",F27=""),"Falta año, mes, país o motivo",IF(AND(C27="Ecuador",E27=""),"Falta la ciudad","OK")))) -> OK
A28: 2025 | B28: Agosto | C28: Argentina | D28: =IF(E28="","",IFERROR(VLOOKUP(E28,'_Catalogos'!$J$2:$K$1000,2,FALSE),"")) | F28: Descanso | G28: 1 | H28: 2 | L28: 1 | M28: 1 | P28: =IF(COUNT(G28:O28)=0,"",SUM(G28:J28)) -> 3 | Q28: =IF(COUNT(G28:O28)=0,"",SUM(K28:N28)) -> 2 | R28: =IF(P28="","",P28+Q28) -> 5 | S28: =IF(R28="","",IF(C28="Ecuador",R28,0)) -> 0 | T28: =IF(R28="","",R28-S28) -> 5 | U28: =IF(R28="","",IF(O28>R28,"Revisar: discapacidad "&O28&" mayor que el total "&R28,IF(OR(A28="",B28="",C28="",F28=""),"Falta año, mes, país o motivo",IF(AND(C28="Ecuador",E28=""),"Falta la ciudad","OK")))) -> OK
A29: 2025 | B29: Septiembre | C29: Ecuador | D29: =IF(E29="","",IFERROR(VLOOKUP(E29,'_Catalogos'!$J$2:$K$1000,2,FALSE),"")) -> Imbabura | E29: Ibarra | F29: Gastronomía | G29: 3 | H29: 3 | I29: 2 | K29: 1 | L29: 2 | M29: 2 | P29: =IF(COUNT(G29:O29)=0,"",SUM(G29:J29)) -> 8 | Q29: =IF(COUNT(G29:O29)=0,"",SUM(K29:N29)) -> 5 | R29: =IF(P29="","",P29+Q29) -> 13 | S29: =IF(R29="","",IF(C29="Ecuador",R29,0)) -> 13 | T29: =IF(R29="","",R29-S29) -> 0 | U29: =IF(R29="","",IF(O29>R29,"Revisar: discapacidad "&O29&" mayor que el total "&R29,IF(OR(A29="",B29="",C29="",F29=""),"Falta año, mes, país o motivo",IF(AND(C29="Ecuador",E29=""),"Falta la ciudad","OK")))) -> OK
A30: 2025 | B30: Septiembre | C30: Ecuador | D30: =IF(E30="","",IFERROR(VLOOKUP(E30,'_Catalogos'!$J$2:$K$1000,2,FALSE),"")) -> Loja | E30: Loja | F30: Gastronomía | G30: 2 | H30: 1 | I30: 3 | K30: 1 | L30: 2 | M30: 1 | P30: =IF(COUNT(G30:O30)=0,"",SUM(G30:J30)) -> 6 | Q30: =IF(COUNT(G30:O30)=0,"",SUM(K30:N30)) -> 4 | R30: =IF(P30="","",P30+Q30) -> 10 | S30: =IF(R30="","",IF(C30="Ecuador",R30,0)) -> 10 | T30: =IF(R30="","",R30-S30) -> 0 | U30: =IF(R30="","",IF(O30>R30,"Revisar: discapacidad "&O30&" mayor que el total "&R30,IF(OR(A30="",B30="",C30="",F30=""),"Falta año, mes, país o motivo",IF(AND(C30="Ecuador",E30=""),"Falta la ciudad","OK")))) -> OK
A31: 2025 | B31: Octubre | C31: Ecuador | D31: =IF(E31="","",IFERROR(VLOOKUP(E31,'_Catalogos'!$J$2:$K$1000,2,FALSE),"")) -> Azuay | E31: Cuenca | F31: Turismo | H31: 2 | L31: 1 | N31: 1 | P31: =IF(COUNT(G31:O31)=0,"",SUM(G31:J31)) -> 2 | Q31: =IF(COUNT(G31:O31)=0,"",SUM(K31:N31)) -> 2 | R31: =IF(P31="","",P31+Q31) -> 4 | S31: =IF(R31="","",IF(C31="Ecuador",R31,0)) -> 4 | T31: =IF(R31="","",R31-S31) -> 0 | U31: =IF(R31="","",IF(O31>R31,"Revisar: discapacidad "&O31&" mayor que el total "&R31,IF(OR(A31="",B31="",C31="",F31=""),"Falta año, mes, país o motivo",IF(AND(C31="Ecuador",E31=""),"Falta la ciudad","OK")))) -> OK
A32: 2025 | B32: Octubre | C32: Alemania | D32: =IF(E32="","",IFERROR(VLOOKUP(E32,'_Catalogos'!$J$2:$K$1000,2,FALSE),"")) | F32: Descanso | J32: 1 | L32: 2 | N32: 2 | P32: =IF(COUNT(G32:O32)=0,"",SUM(G32:J32)) -> 1 | Q32: =IF(COUNT(G32:O32)=0,"",SUM(K32:N32)) -> 4 | R32: =IF(P32="","",P32+Q32) -> 5 | S32: =IF(R32="","",IF(C32="Ecuador",R32,0)) -> 0 | T32: =IF(R32="","",R32-S32) -> 5 | U32: =IF(R32="","",IF(O32>R32,"Revisar: discapacidad "&O32&" mayor que el total "&R32,IF(OR(A32="",B32="",C32="",F32=""),"Falta año, mes, país o motivo",IF(AND(C32="Ecuador",E32=""),"Falta la ciudad","OK")))) -> OK
A33: 2025 | B33: Octubre | C33: Italia | D33: =IF(E33="","",IFERROR(VLOOKUP(E33,'_Catalogos'!$J$2:$K$1000,2,FALSE),"")) | F33: Turismo | H33: 2 | J33: 1 | K33: 2 | L33: 5 | M33: 2 | O33: 8 | P33: =IF(COUNT(G33:O33)=0,"",SUM(G33:J33)) -> 3 | Q33: =IF(COUNT(G33:O33)=0,"",SUM(K33:N33)) -> 9 | R33: =IF(P33="","",P33+Q33) -> 12 | S33: =IF(R33="","",IF(C33="Ecuador",R33,0)) -> 0 | T33: =IF(R33="","",R33-S33) -> 12 | U33: =IF(R33="","",IF(O33>R33,"Revisar: discapacidad "&O33&" mayor que el total "&R33,IF(OR(A33="",B33="",C33="",F33=""),"Falta año, mes, país o motivo",IF(AND(C33="Ecuador",E33=""),"Falta la ciudad","OK")))) -> OK
